Workbook

Sheet Puntos abiertos
A1: ID | B1: Origen | C1: Sev. | D1: Punto | E1: Tipo | F1: Responsable | G1: Módulos | H1: Criterio de cierre | I1: Depende de | J1: Estado | K1: Qué cambió el programador | L1: Módulos modificados | M1: Evidencia / prueba en celda | N1: Fecha programador | O1: Resultado auditoría | P1: Fecha auditoría | Q1: Nota auditoría
A2: G01 | B2: Gestamp #1 | C2: Medio | D2: Cambiar el nombre del robot Gestamp: "Robot name needs to change" | E2: Configuración en celda | F2: Programador robot (en celda) / Gestamp confirma el formato | G2: am.ini, C/KRC/Roboter/Rdc/RobotData.xml, $ROBNAME (smartHMI) | H2: • Formato confirmado por Gestamp por escrito (correo adjunto a la lista). • En el respaldo, am.ini (RobName) y C/KRC/Roboter/Rdc/RobotData.xml (RobotName) traen el nombre nuevo; el nombre del archivo de respaldo también. • Si el formato confirmado difiere de BMW-03-10-R1, la línea "; Robot 03-10-R1 (...)" de los encabezados se ajusta igual (C02). | I2: C02 | J2: Abierto | O2: Estándar Gestamp | P2: 2026-10-11 | Q2: Su robot de referencia se llama NUT07_10R1 (celda 07, estación 10, robot 1); el respaldo Bosch de R20 se llama G65-03-20-R1-PNW1-WC. Hoy el nuestro es BMW_03_10_R1. Por analogía sería NUT03_10R1: confirmar con Gestamp con esos dos ejemplos.
A3: G02 | B3: Gestamp #2 | C3: Alto | D3: Herramienta de seguridad igual al TCP de la herramienta 1 Gestamp: "Safety Tool is not equal to Default TCP" | E3: Configuración de seguridad | F3: Programador robot / Seguridad | G3: C/KRC/Roboter/Config/User/Common/SafetyConfigData.xml, $config.dat (TOOL_DATA[1]) | H3: • Captura de la herramienta de seguridad 1 con el TCP igual a TOOL_DATA[1] del respaldo. • Checksum nuevo anotado y checklist de aceptación firmado por quien tenga la autorización. | I3: F42 | J3: Abierto | O3: Estándar Gestamp | P3: 2026-10-11 | Q3: La herramienta de seguridad no se ve en texto en ningún respaldo: sigue la captura del smartHMI.
A4: G03 | B4: Gestamp #3 | C4: Alto | D4: Determinar los datos de carga de la herramienta 1 Gestamp: "Tool 1 is used without Load data determination" | E4: Prueba en celda | F4: Programador robot / Puesta en marcha | G4: $config.dat (LOAD_DATA[1]), KRC/STEU/Mada/$custom.dat ($LDC_CONFIG[1]) | H4: • LOAD_DATA[1] en $config.dat ya no es {M 210, CM {X 270, Y 0, Z 240}, J {105, 105, 105}}: trae masa, centro de masa e inercias determinados. • Protocolo de Load Data Determination (captura o archivo) con fecha. | I4: C08, F39, C09 | J4: Abierto | O4: Estándar Gestamp | P4: 2026-10-11 | Q4: Gestamp tiene una carga determinada por herramienta (LOAD_DATA[1] 81 kg con centro de masa e inercias) y no usa carga aparte con pieza: se quita ese criterio (igual que R20). Hoy LOAD_DATA[1] sigue tecleado (210 kg, CM 270/0/240, inercias 105).
A5: G04 | B5: Gestamp #4 | C5: Bajo | D5: Programa RedRabbit bloqueado: borrado Gestamp: "Program Red Rabbit() is blocked, might be an unnecessary copy" | E5: Código | F5: Programador robot (prueba en celda) | G5: KRC/R1/Program/Utilities/redrabbit.src, KRC/R1/Program/Utilities/RedRabbit.dat | H5: • En el respaldo no están KRC/R1/Program/Utilities/redrabbit.src ni RedRabbit.dat (borrados también en el controlador). • El programa carga sin errores de compilación (captura del navegador del smartPAD sin módulos en rojo). Un ciclo red rabbit (option 12) corre igual que antes de la carga (sus defectos siguen en F19). Anotar fecha. | I5: G05 | J5: Se cierra con otro punto | O5: Cambio de base | P5: 2026-10-11 | Q5: Base = programa del programador (respaldo del 2026-10-05 14:46). redrabbit.src y RedRabbit.dat siguen en el controlador: son módulos sobrantes y se siguen solo en G05.
A6: G05 | B6: Gestamp #5 | C6: Bajo | D6: Programas sin uso Gestamp: "Unused programs" | E6: Código + configuración | F6: Programador robot / Gestamp controles | G6: KRC/R1/Program/Centerline/centerline_loop.src, KRC/R1/safetest.src, KRC/R1/Program/MoveToPurge.src, KRC/R1/TP/GLUETECH, 11 módulos borrados por la depuración (tools/cleanup_allowlist) | H6: • Con la celda probada al 100 %: los módulos sobrantes de la lista ya no están en el respaldo (borrados en el controlador: un restore no borra archivos). • safetest: decisión de Gestamp anotada en la lista; si se borra, no está en el respaldo; si se queda, su encabezado dice para qué prueba es y quién la usa. • GlueTech desinstalado: no aparece en la lista de paquetes del smartHMI, y ni KRC/R1/TP/GLUETECH ni Program/MoveToPurge.src están en el respaldo. • El programa carga sin errores de compilación (captura del navegador del smartPAD sin módulos en rojo). Un ciclo completo en automático sale bien. Anotar fecha. | I6: G04, C28 | J6: Abierto | O6: Decisión | P6: 2026-10-11 | Q6: Base = programa del programador (respaldo del 2026-10-05 14:46). Decisión de Edgar (2026-10-11, igual que R20): la auditoría ya no marca los módulos que borró la oficina; los sobrantes se siguen solo en este punto y no se evalúan hasta que la celda esté probada al 100 %.
A7: G06 | B7: Gestamp #6 | C7: Medio | D7: Cambio de electrodo: confirmación de 0.1 s y sin handshake Gestamp: "Electrode change confirmation only 0.1 s, no handshake" | E7: Decisión + código | F7: Programador robot / Gestamp controles | G7: KRC/R1/Program/Utilities/gunelectrodechange.src, KRC/R1/cell.src | H7: • Se cumplen los criterios de F43. | I7: F43, F12 | J7: Requiere decisión | O7: Estándar Gestamp | P7: 2026-10-11 | Q7: El cell.src de Gestamp llama GunElectrodeChange() cuando do111Gun1ElectrodeChange (fin de stepper, escrito por AutomationCore_BKG) está activo. El nuestro ya lo hace igual (cell.src:70-71, BKG activo). Depende de que Gestamp resetee el stepper en el Bosch; en R20 la llamada está comentada porque allá el fin de stepper está siempre activo: confirmar en celda que aquí no.
A8: G07 | B8: Gestamp #7 | C8: Alto | D8: Options 1, 2, 7 y 8 de Style_1 llaman el mismo programa Gestamp: "Multiple options in Style_1 call the same sub-program" | E8: Decisión Gestamp + código | F8: Gestamp controles / Programador robot | G8: KRC/R1/Program/Styles/style_1.src, KRC/R1/Program/Styles/Options/style1opt1.src, KRC/R1/Program/StyleApps/Options/style1app2opt1.src, KRC/R1/Program/StyleApps/Options/style1app2opt2.src | H8: • Definición de options por escrito de Gestamp. • Se cumplen los criterios de F02. • Comentarios del código cambiado según docs/CONVENTIONS.md (inglés, señal con dirección y nombre); ningún encabezado de inline form ni línea dentro de un fold de form cambia sin estar declarado (F32, F21, F31). | I8: F02 | J8: Requiere decisión | O8: Estándar Gestamp | P8: 2026-10-11 | Q8: Gestamp usa un option por estación de pick (1 = estación 1, 2 = estación 2, 10 = red rabbit), cada uno con su programa Style1OptN. El nuestro manda 1, 2, 7 y 8 a Style1Opt1 (la estación la decide di065/di066) y 12 al red rabbit. Se cambia o lo acepta Gestamp (igual que R20).
A9: G08 | B9: Gestamp #8 | C9: Alto | D9: El ciclo red rabbit no sigue el camino de producción Gestamp: "Separate Auto-Red Rabbit program that doesn't match production" | E9: Decisión + código | F9: Gestamp controles / Programador robot | G9: KRC/R1/Program/Styles/Options/Style1Opt10AutoRR.src, KRC/R1/Program/StylePicks/Options/style1pick1opt1AutoRR.src, KRC/R1/Program/StyleDrops/Options/style1drop1opt2AutoRR.src | H9: • Procedimiento red rabbit de Gestamp por escrito. • Se cumplen los criterios de F19. • Comentarios del código cambiado según docs/CONVENTIONS.md (inglés, señal con dirección y nombre); ningún encabezado de inline form ni línea dentro de un fold de form cambia sin estar declarado (F32, F21, F31). | I9: F19, G21 | J9: Aceptado sin cambio | O9: Estándar Gestamp | P9: 2026-10-11 | Q9: El red rabbit de Gestamp (Style1Opt10AutoRR) tiene pick y drop propios y usa el nut check de producción. El nuestro tiene la misma estructura y además corre la cámara. Aceptado sin cambio (igual que R20); el cierre final lo acepta Gestamp. El resultado sigue en G21/F19.
A10: G09 | B10: Gestamp #9 | C10: Medio | D10: Pieza en gripper al PLC fijada por programa, no por los sensores Gestamp: "Part control to PLC is set/reset instead of reflecting the real part controls" | E10: Decisión + código | F10: Programador robot / Gestamp controles | G10: KRC/R1/Program/StylePicks/Options/style1pick1opt1.src, KRC/R1/Program/StylePicks/Options/style1pick1opt2.src, KRC/R1/Program/StylePicks/Options/style1pick1opt1AutoRR.src, KRC/R1/Program/StyleDrops/Options/style1drop1opt1.src, KRC/R1/Program/StyleDrops/Options/style1drop1opt2AutoRR.src, KRC/R1/Program/Utilities/RejectGE4.src, KRC/R1/System/sps.sub | H10: • $OUT[18] se escribe en un solo lugar, a partir de di253/di254; los inline forms OUT 18 de picks, drops y RejectGE4 ya no están. • Prueba: quitar la pieza a mano del gripper en T1 → $OUT[18] OFF de inmediato; con la pieza tomada → ON. Anotar fecha. • Comentarios del código cambiado según docs/CONVENTIONS.md (inglés, señal con dirección y nombre); ningún encabezado de inline form ni línea dentro de un fold de form cambia sin estar declarado (F32, F21, F31). | I10: F12, C01, C16 | J10: Aceptado sin cambio | O10: Estándar Gestamp | P10: 2026-10-11 | Q10: Gestamp pone y quita $OUT[18] con inline forms OUT en pick, drop y reject; el nuestro igual (picks, drop al conveyor, drop red rabbit y RejectGE4). Aceptado sin cambio (igual que R20); el cierre final lo acepta Gestamp.
A11: G10 | B11: Gestamp #10 | C11: Medio | D11: Comandos de gripper GripperTech en todos los movimientos de gripper Gestamp: "Gripper commands not used at all times" | E11: Código + prueba en celda | F11: Programador robot / Puesta en marcha | G11: KRC/R1/Program/StylePicks/Options/style1pick1opt1.src, KRC/R1/Program/StylePicks/Options/style1pick1opt2.src, KRC/R1/Program/StylePicks/Options/style1pick1opt1AutoRR.src, KRC/R1/Program/StyleDrops/Options/style1drop1opt1.src, KRC/R1/Program/StyleDrops/Options/style1drop1opt2AutoRR.src, KRC/R1/Program/Utilities/RejectGE4.src, KRC/R1/TP/GripperSpotTech/grp_data.dat, C/KRC/User/TP/Gripper_SpotTech/GripperConfig.xml | H11: • Se cumplen los criterios de F31 y F33. • Prueba en el smartPAD: abrir y confirmar (Cmd OK) un form Gripper SET de un pick y el del drop al conveyor sin cambiar nada; en el respaldo siguiente la llamada sigue siendo GRPg_SetStateAndCheck(1, ...) con el mismo estado. Un ciclo completo en automático de estación 1 y de estación 2. Anotar fecha. | I11: F31, F33 | J11: Se cierra con otro punto | O11: Estándar Gestamp | P11: 2026-10-11 | Q11: Gestamp usa GRPg_SetStateAndCheck / GRPg_Check en pick, drop y reject. El nuestro ya los usa en los 3 picks, el drop al conveyor, el drop red rabbit y RejectGE4, sin salidas de gripper escritas a mano. Queda F31 (el drop red rabbit suelta con el gripper 3) y F33.
A12: G11 | B12: Gestamp #11 | C12: Medio | D12: Sin GOTO ni etiquetas Gestamp: "Use of Goto labels" | E12: Código + prueba en celda | F12: Programador robot (prueba en celda) | G12: KRC/R1/Program/Centerline/centerline_weld.src, KRC/R1/Program/StyleApps/Options/style1app1opt1.src, KRC/R1/Program/StyleApps/Options/style1app1opt2.src, KRC/R1/Program/StyleApps/Options/style1app1opt3.src, KRC/R1/Program/StyleApps/Options/style1app2opt1.src, KRC/R1/Program/StylePicks/Options/style1pick1opt1.src, KRC/R1/Program/StylePicks/Options/style1pick1opt2.src, KRC/R1/Program/StylePicks/Options/style1pick1opt1AutoRR.src, KRC/R1/Program/Styles/Options/style1opt1.src | H12: • En el respaldo ningún módulo del integrador (KRC/R1/Program, KRC/R1/cell.src, sps.sub) tiene GOTO ni etiquetas. • Prueba en celda: un ciclo sin dry cycle de estación 1 y uno de estación 2 (T1 y automático), un rechazo por nut check (option 1), un ciclo red rabbit (option 12), un pick en dry cycle (sin espera de pieza; el ciclo se sigue colgando en la primera weld app por F04, igual que antes) y el timeout de gun cerrado en T1 sin tuerca (HALT, START: vuelve a dar timeout si sigue sin cerrar). Anotar fecha y resultado de cada uno. | I12: F30, F07 | J12: Cerrado - auditado | O12: Cambio de base | P12: 2026-10-11 | Q12: Base = programa del programador (respaldo del 2026-10-05 14:46). Ningún módulo activo tiene GOTO ni etiquetas: el programador los cambió por IF/LOOP (encabezados "Rev. 2026-10-05" de CENTERLINE_WELD y Style1Opt1). Solo quedan GOTO en trigger1-3, módulos sobrantes de G05.
A13: G12 | B13: Gestamp #12 | C13: Medio | D13: Nombres de señal en lugar de números de E/S Gestamp: "Use of I/O numbers instead of signal names" | E13: Código + prueba en celda | F13: Programador robot (prueba en celda) | G13: KRC/R1/Program/Centerline/centerline_weld.src, KRC/R1/Program/Centerline/PRELOAD.src, KRC/R1/Program/Centerline/CENTERLINE_HOME.src, KRC/R1/System/sps.sub, KRC/R1/TP/AutomationCore/automationcoreroutines.dat, KRC/R1/System/$config.dat | H13: • En el respaldo ninguna línea ejecutable del integrador fuera de un inline form KUKA usa $IN[n]/$OUT[n] literal (la auditoría lo revisa). • El programa carga sin errores de compilación (captura del navegador del smartPAD sin módulos en rojo). Un ciclo completo en automático sale bien. Anotar fecha. | I13: F17, C23, F29 | J13: Abierto | O13: Estándar Gestamp | P13: 2026-10-11 | Q13: Gestamp usa inline forms estándar con $IN/$OUT numéricos: eso se acepta. Su lógica escrita a mano es el paquete NutWeld, con señales declaradas por nombre. En R20 solo quedaron números en módulos sobrantes y textos de mensaje (G12 cerrado allá).
A14: G13 | B14: Gestamp #13 | C14: Medio | D14: Código simplificado (nut present en una línea, duplicados fuera) Gestamp: "Poor programming (10 lines for nut present)" | E14: Código + prueba en celda | F14: Programador robot (prueba en celda) | G14: KRC/R1/Program/StyleApps/Options/style1app2opt1.src, KRC/R1/Program/Centerline/centerline_weld.src, KRC/R1/Program/StylePicks/Options/style1pick1opt1.src, KRC/R1/Program/StylePicks/Options/style1pick1opt2.src, KRC/R1/Program/StylePicks/Options/style1pick1opt1AutoRR.src, KRC/R1/Program/StyleDrops/Options/style1drop1opt1.src, KRC/R1/Program/Utilities/RejectGE4.src | H14: • Prueba en automático con option 1: 5 ciclos con pieza buena sin rechazo por tuercas; un ciclo con una tuerca faltante (o una pieza red rabbit) termina en RejectGE4; PARTPRESENT1..3 leídos en el display de variables. En cada pick, drop y reject el gripper confirma su estado con GRPg_SetStateAndCheck, sin el GRPg_Check extra. Anotar fecha y resultado. | I14: F28, F03, F31 | J14: Abierto | O14: Estándar Gestamp | P14: 2026-10-11 | Q14: Gestamp revisa las tuercas en un solo IF con WAIT SEC 0.2 antes de leer.
A15: G14 | B15: Gestamp #14 | C15: Medio | D15: Revisar gripper vacío antes del comando de gripper Gestamp: "Gripper opened before the part control check" | E15: Código + prueba en celda | F15: Programador robot (prueba en celda) | G15: KRC/R1/Program/StylePicks/Options/style1pick1opt1.src, KRC/R1/Program/StylePicks/Options/style1pick1opt2.src, KRC/R1/Program/StylePicks/Options/style1pick1opt1AutoRR.src | H15: • En los tres picks la espera de gripper vacío está antes del primer comando de gripper. • Prueba en T1: con una pieza en el gripper al iniciar el pick, el robot se queda en la espera sin mover el gripper. Anotar fecha. | J15: Abierto | O15: Estándar Gestamp | P15: 2026-10-11 | Q15: Gestamp revisa el estado del gripper (cilindros, pieza ausente) antes de mandarlo. En R20 sigue abierto con el mismo cambio.
A16: G15 | B16: Gestamp #15 | C16: Bajo | D16: Nombres, variables y comentarios en inglés Gestamp: "Names, variables and comments not in English" | E16: Código | F16: Programador robot (prueba en celda) | G16: KRC/R1/TP/AutomationCore/automationcoreroutines.dat, KRC/R1/System/$config.dat, KRC/R1/Program/Centerline/PRELOAD.src, KRC/R1/Program/Centerline/Request_next_nut.src, KRC/R1/Program/StylePicks/Options/style1pick1opt1.src, KRC/R1/Program/StylePicks/Options/style1pick1opt2.src, KRC/R1/Program/StylePicks/Options/style1pick1opt1AutoRR.src, KRC/R1/Program/StyleApps/Options/style1app2opt1.src, KRC/R1/Program/StyleApps/Options/style1app2opt2.src, KRC/R1/Program/Styles/Options/style1opt1.src, KRC/R1/Program/Styles/Options/Style1Opt10AutoRR.src, KRC/R1/Program/Utilities/RejectGE4.src | H16: • La auditoría no encuentra comentarios en español ni los nombres viejos (NUT_STAR, Judment, Rejeted, di227SensorCamera) en código ejecutable ni en declaraciones del respaldo. • En el controlador ya no existe la carpeta KRC/R1/Program/Styles/optiones: style1opt1 y Style1Opt10AutoRR están solo en Styles/Options (la carpeta vieja se borra a mano; si queda, hay dos módulos con el mismo nombre). • El programa carga sin errores de compilación (captura del navegador del smartPAD sin módulos en rojo). Un ciclo completo en automático sale bien. Anotar fecha. | I16: C26, F36 | J16: Abierto | O16: Estándar Gestamp | P16: 2026-10-11 | Q16: Como en R20: NUT_STAR es error de dedo, no español, y no impide el cierre.
A17: G16 | B17: Gestamp #16 | C17: Medio | D17: Constantes para límites de carrera, presiones y tiempos Gestamp: "NO variables for e.g. stroke limits" | E17: Código + prueba en celda | F17: Programador robot (prueba en celda) | G17: KRC/R1/System/$config.dat, KRC/R1/Program/Centerline/centerline_weld.src, KRC/R1/Program/Centerline/CENTERLINE_HOME.src | H17: • No quedan esos números en líneas ejecutables de CENTERLINE_WELD / CENTERLINE_HOME. • Un ciclo de soldadura completo en automático; valores leídos en el display de variables iguales a los del fold CENTERLINE CONTROL. Anotar fecha. | I17: F16, F44, F41 | J17: Abierto | O17: Estándar Gestamp | P17: 2026-10-11 | Q17: Gestamp guarda los parámetros de soldadura en datos (nutwelddata.dat). En R20 se pasaron a $config.dat.
A18: G17 | B18: Gestamp #17 | C18: Bajo | D18: Lógica Nut_weld_Retry inútil Gestamp: "Nut_weld_Retry logic useless" | E18: Código | F18: Programador robot (prueba en celda) | G18: KRC/R1/Program/StyleApps/Options/style1app1opt1.src, KRC/R1/Program/StyleApps/Options/style1app1opt2.src, KRC/R1/Program/StyleApps/Options/style1app1opt3.src, KRC/R1/System/$config.dat | H18: • NUT_WELD_RETRY y RETRY_NUT1 no aparecen en el respaldo. • Un ciclo completo en automático con las 3 tuercas, sin errores. Anotar fecha. | I18: F24 | J18: Abierto | O18: Estándar Gestamp | P18: 2026-10-11 | Q18: El retry de Gestamp sí funciona (REPEAT UNTIL bNutFeedOK, tope nMaxDumpNutRetries=10). El nuestro nunca se activa: lo más simple es borrarlo, como en R20.
A19: G18 | B19: Gestamp #18 | C19: Alto | D19: Sin chequeo de soldadura buena Gestamp: "NO check for Weld OK, just weld finished" | E19: Código + prueba en celda | F19: Programador robot / Puesta en marcha | G19: KRC/R1/Program/Centerline/centerline_weld.src, KRC/R1/Program/Styles/Options/style1opt1.src | H19: • Se cumplen los criterios de F08. | I19: F08 | J19: Aceptado sin cambio | O19: Estándar Gestamp | P19: 2026-10-11 | Q19: El paquete NutWeld de Gestamp (WeldInitiate) solo espera WeldComplete, con timeout, reintentos y diálogo; no lee falla ni weld OK. El nuestro también toma WeldComplete como soldadura buena: en weld OK es igual a su respaldo. Aceptado sin cambio; el cierre final lo acepta Gestamp. El timeout y el mensaje de esa espera siguen en F15/C21.
A20: G19 | B20: Gestamp #19 | C20: Alto | D20: Handshake de la tuerca frágil ante selección de bloque, reset y reinicio Gestamp: "Next_Nut_Ready logic can fail at block selection, reset, reboot" | E20: Código + prueba en celda | F20: Programador robot | G20: KRC/R1/Program/Centerline/PRELOAD.src, KRC/R1/Program/Centerline/Request_next_nut.src, KRC/R1/System/$config.dat, KRC/R1/cell.src, KRC/R1/System/sps.sub, KRC/R1/Program/StyleApps/Options/style1app1opt1.src, KRC/R1/Program/StyleApps/Options/style1app1opt2.src, KRC/R1/Program/StyleApps/Options/style1app1opt3.src, KRC/R1/Program/StylePicks/Options/style1pick1opt1.src, KRC/R1/Program/StylePicks/Options/style1pick1opt2.src | H20: • Se cumplen los criterios de F38 y F14. | I20: F38, F14 | J20: Abierto | O20: Alta (Gestamp) | P20: 2026-10-04 | Q20: Punto 19 de la revisión de Gestamp del 2026-10-02 (BMW-03-10R1).
A21: G20 | B21: Gestamp #20 | C21: Alto | D21: Request_next_nut y NUT_START fuera de los inline forms Gestamp: "Change of xP0 deletes Request_next_nut inside inline forms" | E21: Código + prueba en celda | F21: Programador robot (prueba en celda) | G21: KRC/R1/Program/StylePicks/Options/style1pick1opt1.src, KRC/R1/Program/StylePicks/Options/style1pick1opt2.src, KRC/R1/Program/StylePicks/Options/style1pick1opt1AutoRR.src, KRC/R1/Program/StyleApps/Options/style1app1opt1.src, KRC/R1/Program/StyleApps/Options/style1app1opt2.src, KRC/R1/Program/StyleDrops/Options/style1drop1opt2AutoRR.src | H21: • Ningún fold de inline form contiene líneas escritas a mano (la auditoría lo revisa). • Prueba: abrir el inline form PTP P12 de style1pick1opt1 y PTP P0 de style1app1opt1 y confirmarlos con Cmd OK sin cambiar nada (sin Touch Up, que reenseña el punto); el TRIGGER sigue antes de cada fold. Después, un ciclo completo en automático: NUT_READY y NEXT_NUT_READY (display de variables) pasan a FALSE y vuelven a TRUE una vez por tuerca (3 preloads por pieza). Anotar fecha. | I21: F32, F14 | J21: Abierto | O21: Estándar Gestamp | P21: 2026-10-11 | Q21: Gestamp no mete código propio dentro de los folds. En R20 se cerró cuando Request_next_nut y NUT_START quedaron fuera.
A22: G21 | B22: Gestamp #21 | C22: Alto | D22: El nut check no funciona para red rabbit Gestamp: "Style1app2Opt1 will not work for RedRabbit" | E22: Decisión + código | F22: Gestamp controles / Programador robot | G22: KRC/R1/Program/StyleApps/Options/style1app2opt1.src, KRC/R1/Program/StyleApps/Options/style1app2opt2.src, KRC/R1/Program/Styles/Options/Style1Opt10AutoRR.src | H22: • Red rabbit con la lógica de Gestamp: FAILED si hay cualquier tuerca (OR), PASSED si no hay ninguna. • do141/do142 ya no se borran en el drop red rabbit (solo en MaintainSystem o donde lo pida el PLC). • La cámara no escribe un resultado contrario en el red rabbit (Gestamp no la corre ahí). • Prueba del red rabbit con la pieza red rabbit y con una pieza buena; anotar fecha y lo que ve el PLC. | I22: F19, G08 | J22: Abierto | O22: Estándar Gestamp | P22: 2026-10-11 | Q22: Gestamp (Style1App2Opt4): FAILED si hay cualquier tuerca (OR), PASSED si no hay ninguna; los resultados los borra solo MaintainSystem, nunca el drop. El nuestro da FAILED solo con las 3 tuercas (style1app2opt1.src:147-154) y el drop red rabbit borra do141/do142 dentro del fold DropOff[2] Reset (style1drop1opt2AutoRR.src:154-155): el PLC puede no ver el resultado.
A23: G22 | B23: Gestamp #22 | C23: Alto | D23: Uso incorrecto de AutomationCore Gestamp: "Use of AutomationCore is wrong in multiple places" | E23: Decisión Gestamp + código | F23: Gestamp controles / Programador robot | G23: KRC/R1/System/sps.sub, KRC/R1/TP/AutomationCore/automationcoreroutines.src, inline forms AutomationCore, KRC/R1/Program/Utilities/RejectGE4.src, KRC/R1/Program/Styles/Options/style1opt1.src, KRC/R1/cell.src, KRC/R1/Program/masref_user.src | H23: • Lista de Gestamp recibida y anotada aquí. • Cada lugar de la lista corregido y auditado. | I23: F12, C01, F46, F21, F20, C11, C12, C18, C19, C14, F35 | J23: Abierto | O23: Estándar Gestamp | P23: 2026-10-11 | Q23: Gestamp nunca mandó su lista. Comparado con NUT07_10R1: C01 y C19 cumplen (AutomationCore_BKG activo, mismo código que R20), C14 queda solo en F47 y C12 se acepta (Gestamp no usa pounce en el ciclo). Quedan F12 (señales de NutWeld_BKG que usa el PLC), F20 (liberar Application 1 en el rechazo por nut check), F21 (5 forms con AC_CmdParam distinto a la llamada) y F46 (Work Complete).
A24: F01 | B24: Ethos | C24: Crítico | D24: Entrada al pedestal sin confirmar gun abierto, clamp abierto y QFP regresado | E24: Código + prueba en celda | F24: Programador robot | G24: KRC/R1/Program/StyleApps/Options/style1app1opt1.src, KRC/R1/Program/StyleApps/Options/style1app1opt2.src, KRC/R1/Program/StyleApps/Options/style1app1opt3.src, KRC/R1/Program/Centerline/PRELOAD.src, KRC/R1/Program/Centerline/centerline_weld.src | H24: • En style1app1opt1, opt2 y opt3, inmediatamente antes del LIN de aproximación (P20, P6 y P13 respectivamente), después de la espera de NUT_READY / NEXT_NUT_READY y fuera de cualquier fold de inline form, existe una espera supervisada (timeout + mensaje + $OUT[4] do004ProcessFault) de: CL_GunStrokePositionLPT > CL_GUN_OPEN_MIN, $IN[466] di466PartClampOpen ON, $IN[482] dipw1_SpearHome ON y $IN[470] di470QFPAdvanced OFF. Corre también en dry cycle, porque el LIN de aproximación se ejecuta en los dos casos. • La espera detiene el advance run (WAIT FOR, o WAIT SEC 0 antes de una evaluación con IF o lazo): la condición sobre CL_GunStrokePositionLPT, que es una variable y no una entrada, no se evalúa por adelantado. • En PRELOAD, paso 20: STEP20DONE (y por tanto NUT_READY / NEXT_NUT_READY = TRUE) exige $IN[482] dipw1_SpearHome ON además de $TIMER[12]. • Prueba en T1 con override reducido, una por condición: clamp no abierto, QFP no regresado y gun no abierto (sensor desconectado o válvula sin aire). En cada caso el robot se detiene antes del LIN de aproximación con el mensaje que nombra la condición y $OUT[4] ON, y continúa solo al corregirla. Anotar fecha, override y resultado de cada caso. • Comentarios del código cambiado según docs/CONVENTIONS.md (inglés, señal con dirección y nombre); ningún encabezado de inline form ni línea dentro de un fold de form cambia sin estar declarado (F32, F21, F31). | J24: Abierto | O24: Integrado - correcciones de la revisión | P24: 2026-10-05 | Q24: Versión integrada sobre el respaldo de las 14:46: INTERRUPT ON 20-22 antes de cada GUN_OPEN_CHECK (entrada y después de soldar) y mensaje de estado en GUN_OPEN_LOST después del reconocimiento. Sigue pendiente clamp abierto / QFP regresado antes de entrar.
A25: F02 | B25: Ethos | C25: Alto | D25: Options 2, 7 y 8 no evalúan el sensor de tuercas: solo decide la cámara | E25: Código + prueba en celda | F25: Programador robot + Gestamp controles | G25: KRC/R1/Program/StyleApps/Options/style1app2opt1.src, KRC/R1/Program/StyleApps/Options/style1app2opt2.src, KRC/R1/Program/Styles/style_1.src, KRC/R1/Program/Styles/Options/style1opt1.src | H25: • Respuesta escrita del programador PLC (Gestamp) con la lista de options que manda producción, adjunta a la lista. • En style1app2opt1 toda option de producción que llega a Style1Opt1 (1, 2, 7, 8 o las confirmadas) entra en la evaluación del sensor; ninguna sale sin escribir bscrapGE4. • bscrapGE4 = TRUE se asigna antes de leer $IN[227] di227NutPresent1 (nut check) y antes de pedir la cámara con $OUT[80] do080RepositionTooling1; bscrapGE4 = FALSE solo aparece en la rama de pase. En la cámara, una combinación de $IN[100]/$IN[101] distinta de OK ON y NG OFF deja la pieza en scrap. • Ninguna option pasa en silencio: una option que no es de producción ni red rabbit da mensaje y $OUT[4] do004ProcessFault y bscrapGE4 queda en TRUE. • Prueba en celda con option 2 (y 7/8 si producción las usa): (1) pieza con una tuerca faltante termina en RejectGE4 aunque la cámara dé OK (cámara simulada desde el PLC); (2) pieza con las 3 tuercas termina en Style1Drop1Opt1; (3) cámara NG termina en RejectGE4. Anotar fecha, option, caso y destino de la pieza. • Comentarios del código cambiado según docs/CONVENTIONS.md (inglés, señal con dirección y nombre); ningún encabezado de inline form ni línea dentro de un fold de form cambia sin estar declarado (F32, F21, F31). | I25: G07 | J25: Se cierra con otro punto | O25: Cambio de base | P25: 2026-10-11 | Q25: Base = programa del programador (respaldo del 2026-10-05 14:46). El nut check ya evalúa las options 1, 2, 7 y 8 y escribe bScrapGE4 TRUE o FALSE (style1app2opt1.src:140-145). Queda la definición de options: G07.
A26: F03 | B26: Calvin #8 | C26: Alto | D26: PARTPRESENT1..3 y bscrapGE4 no se resetean al inicio del ciclo | E26: Código + prueba en celda | F26: Programador robot | G26: KRC/R1/Program/Styles/Options/style1opt1.src, KRC/R1/Program/Styles/Options/Style1Opt10AutoRR.src, KRC/R1/Program/StyleApps/Options/style1app2opt1.src, KRC/R1/System/$config.dat | H26: • En Style1Opt1, antes de cualquier pick, PARTPRESENT1..3 = FALSE y bscrapGE4 = TRUE. • En Style1Opt10AutoRR, antes del pick, PARTPRESENT1..3 = FALSE (el nut check es compartido con el red rabbit). • En style1app2opt1 cada uno de los 3 checks asigna PARTPRESENTn = di227NutPresent1 (TRUE o FALSE) (hecho en oficina, G13). • Prueba en celda: cancelar un ciclo después del nut check (p. ej. en la espera de $IN[80] di080ToolRepositioned1), reiniciar y verificar en la pantalla de variables que PARTPRESENT1..3 = FALSE y bscrapGE4 = TRUE antes de llegar al nut check. Anotar fecha y valores leídos. • Comentarios del código cambiado según docs/CONVENTIONS.md (inglés, señal con dirección y nombre); ningún encabezado de inline form ni línea dentro de un fold de form cambia sin estar declarado (F32, F21, F31). | I26: F02 | J26: Abierto | O26: Auditoría - sin cambio | P26: 2026-10-05 | Q26: PARTPRESENTn sigue poniéndose solo en TRUE y se lee antes del WAIT SEC 0.2; se limpia al final de Style1Opt1, no al inicio.
A27: F04 | B27: Ethos | C27: Alto | D27: Dry cycle se cuelga en la primera weld app: PRELOAD borra NUT_READY y nunca lo pone | E27: Código + prueba en celda | F27: Programador robot | G27: KRC/R1/Program/StyleApps/Options/style1app1opt1.src, KRC/R1/Program/StyleApps/Options/style1app1opt2.src, KRC/R1/Program/StyleApps/Options/style1app1opt3.src, KRC/R1/Program/Centerline/PRELOAD.src, KRC/R1/Program/Centerline/Request_next_nut.src, KRC/R1/Program/StylePicks/Options/style1pick1opt1.src, KRC/R1/Program/StylePicks/Options/style1pick1opt2.src, KRC/R1/System/$config.dat | H27: • En style1app1opt1..3, en producción la espera de NUT_READY / NEXT_NUT_READY sigue antes del LIN de aproximación (P20, P6, P13), junto con la espera de F01. Con dry cycle no se ejecuta ninguna espera que dependa de PRELOAD. • En PRELOAD, con dry cycle activo un NUT_START no deja NUTCYCLE_ACTIVE = TRUE con NUT_READY = FALSE; al terminar un dry cycle no queda un preload iniciado ni un NUT_START pendiente que alimente una tuerca al quitar el dry cycle. • Prueba en celda: con dry cycle desde el inicio, ciclo completo desde la estación 1 y desde la estación 2 hasta el final del ciclo; después, sin dry cycle, un ciclo productivo con una sola tuerca alimentada para cada soldadura (sin doble tuerca ni espera infinita). Anotar fecha y resultado. • Comentarios del código cambiado según docs/CONVENTIONS.md (inglés, señal con dirección y nombre); ningún encabezado de inline form ni línea dentro de un fold de form cambia sin estar declarado (F32, F21, F31). | J27: Abierto | O27: Alta (Ethos) | P27: 2026-10-04 | Q27: Revisión Ethos del respaldo 658424 (v431_03_10_r1.zip del 2026-10-02).
A28: F05 | B28: Ethos | C28: Alto | D28: Dry cycle releído en cada paso: un cambio a mitad de ciclo deja pasar pieza incompleta | E28: Código + prueba en celda | F28: Programador robot | G28: KRC/R1/Program/StylePicks/Options/style1pick1opt1.src, KRC/R1/Program/StylePicks/Options/style1pick1opt2.src, KRC/R1/Program/StylePicks/Options/style1pick1opt1AutoRR.src, KRC/R1/Program/StyleApps/Options/style1app1opt1.src, KRC/R1/Program/StyleApps/Options/style1app1opt2.src, KRC/R1/Program/StyleApps/Options/style1app1opt3.src, KRC/R1/Program/StyleApps/Options/style1app2opt1.src, KRC/R1/Program/StyleApps/Options/style1app2opt2.src, KRC/R1/Program/Centerline/PRELOAD.src, KRC/R1/Program/Styles/Options/style1opt1.src, KRC/R1/Program/Styles/Options/Style1Opt10AutoRR.src, KRC/R1/System/$config.dat | H28: • Existe una sola bandera de dry cycle declarada con comentario (p. ej. en $config.dat), asignada desde $IN[4] di004UseDryCycle una sola vez al inicio del ciclo, antes del pick, y nada la cambia hasta el final del ciclo. • En los picks, style1app1opt1..3, style1app2opt1, style1app2opt2 y PRELOAD no queda ninguna lectura ejecutable de di004UseDryCycle; solo de la bandera (la de sps.sub para el agua se resuelve en F09). • Con la bandera en TRUE se cumple, y está comentado en el código, uno de: (a) el pick verifica gripper vacío después de cerrar ($IN[253] y $IN[254] OFF) y da falla con mensaje si hay pieza; o (b) la pieza termina en RejectGE4 y nunca en Style1Drop1Opt1. • Prueba en celda en producción (option 1), con la pieza de prueba segregada: activar $IN[4] desde el PLC (1) durante un preload y (2) con el preload de la tuerca 3 terminado y el robot yendo a su pose. En los dos casos el ciclo en curso termina como productivo (3 soldaduras e inspecciones), la celda no se cuelga y el ciclo siguiente corre en dry cycle. Anotar fecha, momento del cambio y destino de la pieza. • Comentarios del código cambiado según docs/CONVENTIONS.md (inglés, señal con dirección y nombre); ningún encabezado de inline form ni línea dentro de un fold de form cambia sin estar declarado (F32, F21, F31). | J28: Abierto | O28: Alta (Ethos) | P28: 2026-10-04 | Q28: Revisión Ethos del respaldo 658424 (v431_03_10_r1.zip del 2026-10-02).
A29: F06 | B29: Ethos | C29: Alto | D29: Ciclos vacíos o silenciosos: pick ambiguo, style u option desconocidos | E29: Código + prueba en celda | F29: Programador robot | G29: KRC/R1/Program/Styles/Options/style1opt1.src, KRC/R1/Program/Styles/style_1.src, KRC/R1/cell.src | H29: • En Style1Opt1, mientras $IN[65] di065PickupMachine1 y $IN[66] di066PickupMachine2 no tengan exactamente una en ON, el robot espera con un mensaje que nombra ambas señales (con ambas en ON además $OUT[4] do004ProcessFault); no existe camino por Style1Opt1 que termine sin pick. • En cell.src, el DEFAULT del SWITCH nStyle muestra mensaje y pone $OUT[4] do004ProcessFault, y un style no ejecutado no llega a EndOfCycle. • En Style_1 no queda WAIT FOR FALSE; el DEFAULT muestra mensaje con el número de option y pone $OUT[4] do004ProcessFault. • En los dos DEFAULT la falla se sostiene hasta que el operador o el PLC la reconoce (diálogo o mensaje con acuse); no es un pulso que MaintainSystem borra en la siguiente vuelta de CELL. • Prueba en celda con el PLC: (1) style distinto de 1, (2) option no válida, (3) $IN[65] y $IN[66] ambas ON, (4) ambas OFF y después una sola en ON. En cada caso hay mensaje en el smartPAD; en (1) a (3) además $OUT[4] ON hasta el acuse; en (4) el ciclo sigue normal al quedar una sola en ON. Anotar fecha y resultado. • Comentarios del código cambiado según docs/CONVENTIONS.md (inglés, señal con dirección y nombre); ningún encabezado de inline form ni línea dentro de un fold de form cambia sin estar declarado (F32, F21, F31). | I29: F02 | J29: Abierto | O29: Alta (Ethos) | P29: 2026-10-04 | Q29: Revisión Ethos del respaldo 658424 (v431_03_10_r1.zip del 2026-10-02).
A30: F07 | B30: Ethos | C30: Alto | D30: Chequeo de gun cerrado: HALT sin mensaje como manejo de falla | E30: Código + prueba en celda | F30: Programador robot | G30: KRC/R1/Program/Centerline/centerline_weld.src | H30: • En CENTERLINE_WELD no queda HALT en el chequeo de gun cerrado. • Al vencer el timeout se muestra un diálogo AutomationCore (Set_KrlDlg o equivalente) con $OUT[4] do004ProcessFault ON, que nombra la falla (según CL_GunStrokePositionLPT respecto a la ventana) y ofrece Retry y Abort. • Retry vuelve a armar el timeout y el tiempo en ventana: un segundo timeout es posible (hecho en oficina para el HALT actual, G11). • Abort abre el gun ($OUT[472] dopw1_GunWork OFF, $OUT[471] dopw1_GunHome ON) y el clamp ($OUT[501] do501PartClampClose OFF, $OUT[502] do502PartClampOpen ON), no da weld start ($OUT[483] dopw1_WeldInit) para esa tuerca, y la pieza termina en RejectGE4. • Prueba en T1, sin pieza, sin nadie en el pedestal y con el timer Bosch sin corriente de soldadura: cerrar el gun sin tuerca en el pin: aparece el diálogo; Retry sin corregir hace que el diálogo vuelva a salir; Abort abre gun y clamp. Anotar fecha, valor de CL_GunStrokePositionLPT leído y resultado. • Comentarios del código cambiado según docs/CONVENTIONS.md (inglés, señal con dirección y nombre); ningún encabezado de inline form ni línea dentro de un fold de form cambia sin estar declarado (F32, F21, F31). | J30: Abierto | O30: Auditoría - avance en el original | P30: 2026-10-05 | Q30: En el original del programador los dos timers se reinician después del HALT (igual que la versión de oficina). Sigue sin mensaje y sin do004ProcessFault: el criterio no se cumple completo.
A31: F08 | B31: Calvin #2 | C31: Alto | D31: Resultado de soldadura Bosch no evaluado: weld complete se toma como soldadura buena | E31: Código + prueba en celda | F31: Programador robot + Gestamp controles | G31: KRC/R1/Program/Centerline/centerline_weld.src, KRC/R1/Program/Styles/Options/style1opt1.src | H31: • Polaridad de $IN[485] confirmada con la lista de I/O de Bosch (documento y página) o con prueba en celda (valor leído con el timer en falla y sin falla), adjunta a la lista. • En CENTERLINE_WELD, después de $OUT[483] dopw1_WeldInit ON, la espera es $IN[483] dipw1_WeldComplete O falla ($IN[485] con la polaridad confirmada) con timeout; el código usa el nombre de $IN[485] que coincide con esa polaridad. • En falla o timeout: presión base (CL_GUN_PRESS_BASE, con el orden de bytes que confirme F44), intensify liberado ($OUT[473] dopw1_Nut1Intensify_Home en reposo, $OUT[494] dopw1_BlowOff OFF), $OUT[483] dopw1_WeldInit OFF, gun abierto, mensaje con $OUT[4] do004ProcessFault, y la pieza termina en RejectGE4 aunque después pasen el nut check y la cámara. • Prueba en celda: provocar una falla del timer Bosch durante una soldadura (o simularla según el manual Bosch): el robot no sigue como soldadura buena, el gun abre, aparece el mensaje y la pieza va a RejectGE4. Anotar fecha, cómo se provocó la falla y resultado. • Comentarios del código cambiado según docs/CONVENTIONS.md (inglés, señal con dirección y nombre); ningún encabezado de inline form ni línea dentro de un fold de form cambia sin estar declarado (F32, F21, F31). | I31: F44 | J31: Aceptado sin cambio | O31: Estándar Gestamp | P31: 2026-10-11 | Q31: El paquete NutWeld de Gestamp (WeldInitiate) solo espera WeldComplete, con timeout, reintentos y diálogo; no lee falla ni weld OK. El nuestro también toma WeldComplete como soldadura buena: en weld OK es igual a su respaldo. Aceptado sin cambio; el cierre final lo acepta Gestamp. El timeout y el mensaje de esa espera siguen en F15/C21.
A32: F09 | B32: Ethos | C32: Alto | D32: Resultado del flujo de agua descartado; $OUT[475] forzado en ON | E32: Código + prueba en celda | F32: Programador robot + Puesta en marcha | G32: KRC/R1/System/sps.sub, KRC/R1/Program/Centerline/centerline_weld.src, KRC/R1/Program/Centerline/CENTERLINE_HOME.src, KRC/R1/Program/Utilities/gunelectrodechange.src, KRC/R1/System/$config.dat | H32: • En sps.sub, con SV0500_FLOW bajo el límite la bandera de agua usada por la soldadura queda en FALSE (ya no hay TRUE en las dos ramas); una sola bandera (CL_WaterOK o dipw1_WaterOk) y la otra se quita o se deja documentada. • En CENTERLINE_WELD, antes de $OUT[483] dopw1_WeldInit ON, existe una espera supervisada (timeout + mensaje + $OUT[4] do004ProcessFault) de agua OK y $IN[475] dipw1_XtfmrTempOk ON; sin ellas no hay weld start. • En sps.sub, $OUT[475] dopw1_StartWater se escribe en ambos sentidos según $IN[13] di013WaterEnable; una sola lógica decide $OUT[475] (el water-off de CENTERLINE_HOME y de gunelectrodechange se respeta o se quita, y el comentario dice quién manda). • El límite de SV0500_FLOW (valor y operador) coincide con un valor confirmado por escrito (Gestamp o CenterLine) y el ;CHECK: del límite en sps.sub se elimina. • Prueba en celda: (1) con $IN[13] OFF, $OUT[475] pasa a OFF; (2) con el agua cerrada el robot no da weld start y muestra mensaje; (3) con agua y transformador normales la soldadura arranca. Anotar fecha y SV0500_FLOW leído con agua normal y con agua cerrada. • Comentarios del código cambiado según docs/CONVENTIONS.md (inglés, señal con dirección y nombre); ningún encabezado de inline form ni línea dentro de un fold de form cambia sin estar declarado (F32, F21, F31). | J32: Abierto | O32: Evidencia parcial | P32: 2026-10-05 | Q32: Respaldo 14:46: nWaterFlow = 233 (23.3 l/min) con agua normal en este robot, arriba del mínimo de 15 l/min. Falta la prueba con agua cerrada y la espera antes del weld start.
A33: F10 | B33: Ethos | C33: Alto | D33: Sin estado seguro del pedestal al cancelar o resetear el programa | E33: Código + prueba en celda | F33: Programador robot | G33: KRC/R1/System/sps.sub, KRC/R1/cell.src, KRC/R1/Program/Centerline/centerline_weld.src | H33: • Existe una rutina de estado seguro del pedestal que se ejecuta cuando el programa se cancela ($PRO_STATE1 = #P_FREE) y cuando se resetea ($PRO_STATE1 = #P_RESET). • La rutina deja: $OUT[483] dopw1_WeldInit OFF, $OUT[481] dopw1_WeldContactEnable OFF, $OUT[482] dopw1_WeldOnExternal OFF, CL_GunPressureCmd = presión base (valor según F44), $OUT[473] dopw1_Nut1Intensify_Home en su reposo, $OUT[494] dopw1_BlowOff OFF, $OUT[476] dopw1_StartFeed OFF. • La rutina deja además gun abierto y clamp abierto, salvo que la revisión de seguridad de F11 decida por escrito que en cancel/reset no se mueven actuadores sin enabling switch; en ese caso no los toca, el comentario cita esa decisión y la protección es el bloqueo de HOME. • En cell.src ningún camino llega a InitializeSystem(), HOME() o HomeCheck() mientras el gun no esté abierto (CL_GunStrokePositionLPT > CL_GUN_OPEN_MIN) o el clamp no esté abierto ($IN[466] di466PartClampOpen ON): espera supervisada con mensaje y $OUT[4] do004ProcessFault, sin movimiento. • Prueba en T1, sin pieza, sin nadie en el pedestal y con el timer Bosch sin corriente: detener CENTERLINE_WELD con el clamp cerrado y cancelar el programa; leer cada salida de la lista. Repetir con reset. Después, con el clamp detectado como no abierto, seleccionar CELL: el robot no se mueve a HOME y muestra mensaje. Anotar fecha y valores leídos. • Comentarios del código cambiado según docs/CONVENTIONS.md (inglés, señal con dirección y nombre); ningún encabezado de inline form ni línea dentro de un fold de form cambia sin estar declarado (F32, F21, F31). | I33: F11, F44 | J33: Abierto | O33: Alta (Ethos) | P33: 2026-10-04 | Q33: Revisión Ethos del respaldo 658424 (v431_03_10_r1.zip del 2026-10-02).
A34: F11 | B34: Ethos | C34: Crítico | D34: PRELOAD en el submit mueve el pedestal en cualquier modo, sin dueño de las salidas | E34: Código + prueba en celda | F34: Seguridad + Programador robot | G34: KRC/R1/System/sps.sub, KRC/R1/Program/Centerline/PRELOAD.src, KRC/R1/Program/Centerline/Request_next_nut.src, KRC/R1/Program/Centerline/centerline_weld.src, KRC/R1/Program/Centerline/CENTERLINE_HOME.src, KRC/R1/Program/StylePicks/Options/style1pick1opt1.src, KRC/R1/Program/StylePicks/Options/style1pick1opt2.src, KRC/R1/System/$config.dat | H34: • Revisión de seguridad documentada (Gestamp / Seguridad) que responde si el aire del pedestal se corta con la puerta abierta, con referencia al plano o a una prueba física con fecha, adjunta a la lista. • En PRELOAD (o en su llamada en sps.sub), el arranque y los pasos están condicionados a $MODE_OP == #EX, $MOVE_ENABLE TRUE y una bandera de liberación declarada que pone y quita el programa del robot; con la condición en FALSE, PRELOAD no escribe ninguna salida del pedestal. • Si la condición cae con un preload a medias, el comportamiento está escrito en un comentario de PRELOAD y un preload interrumpido no puede terminar en NUT_READY / NEXT_NUT_READY = TRUE sin haber completado sus pasos. • PRELOAD no arranca mientras CENTERLINE_WELD o CENTERLINE_HOME están corriendo, y esos programas no escriben válvulas del pedestal mientras NUTCYCLE_ACTIVE es TRUE. • Un NUT_START recibido con un preload activo no produce una bandera de un solo ciclo de submit que el robot pueda tomar como buena. • En T1/T2 el ciclo no se queda esperando NUT_READY sin mensaje. • Prueba en celda, sin nadie en el pedestal: (1) en T1, correr el pick paso a paso hasta pasar P12 y soltar el enabling switch: el pedestal no se mueve; (2) con CELL cancelado, poner NUT_START = TRUE desde la pantalla de variables: el pedestal no se mueve; (3) en automático externo, un ciclo productivo completo alimenta y suelda las 3 tuercas. Anotar fecha y resultado. • Comentarios del código cambiado según docs/CONVENTIONS.md (inglés, señal con dirección y nombre); ningún encabezado de inline form ni línea dentro de un fold de form cambia sin estar declarado (F32, F21, F31). | J34: Requiere decisión | O34: Alta (Ethos) | P34: 2026-10-04 | Q34: Revisión Ethos del respaldo 658424 (v431_03_10_r1.zip del 2026-10-02).
A35: F12 | B35: Ethos | C35: Alto | D35: Background de AutomationCore y NutWeld deshabilitado: los bits de estado al PLC no cambian | E35: Decisión Gestamp | F35: Gestamp controles + Programador robot | G35: KRC/R1/System/sps.sub, KRC/R1/TP/AutomationCore/automationcoreroutines.src, KRC/R1/TP/NutWeld/nutweldroutines.src, KRC/R1/System/$config.dat, KRC/R1/Program/Utilities/pouncetohome.src, KRC/R1/Program/Utilities/gunelectrodechange.src, KRC/R1/cell.src | H35: • Decisión escrita de Gestamp (nombre, fecha): reactivar AutomationCore_BKG y/o NutWeld_BKG, o reproducir los bits en sps.sub. • Si se reactiva AutomationCore_BKG: F35 está cerrado antes; en automationcoreroutines.src ya no hay escrituras de weld enable por dry cycle ni de $OUT[475] que contradigan F09; cada cambio en el archivo del proveedor queda en la lista de C28. • Si se reactiva NutWeld_BKG: F17 está cerrado antes (nombres de pistola 2/3 traslapados con CL_GunPressureCmd). • Si se reproducen en sps.sub: se escriben en cada ciclo $OUT[21], $OUT[22], $OUT[6], $OUT[7], $OUT[46], los bits de nodo de bus que Gestamp pida, $OUT[146], $OUT[145] doCriticalWZ, el nivel de tolva y la petición de cambio de electrodo que se acuerde en F43, con la lógica aprobada por escrito. • En cualquier caso, $OUT[145] doCriticalWZ está en TRUE (entrada no permitida) mientras CENTERLINE_WELD corre o PRELOAD está activo. • Prueba en celda: verificar desde el PLC cada bit que se pueda provocar (p. ej. override < 100 % en automático externo; una solicitud de entrada durante CENTERLINE_WELD no recibe permiso); los demás se revisan en código. Anotar fecha y resultado por bit. • Comentarios del código cambiado según docs/CONVENTIONS.md (inglés, señal con dirección y nombre); ningún encabezado de inline form ni línea dentro de un fold de form cambia sin estar declarado (F32, F21, F31). | I35: F17, F35 | J35: Abierto | O35: Estándar Gestamp | P35: 2026-10-11 | Q35: AutomationCore_BKG activo, como en Gestamp. NutWeld_BKG sigue apagado (en Gestamp está activo): faltan las señales del soldador que usa el PLC. En R20 el programador las replica en sps.sub "como NUT07". Se cierra cuando el PLC recibe las señales que usa.
A36: F13 | B36: Calvin #6 | C36: Medio | D36: PRELOAD sin timeouts por paso, sin falla y banderas de tuerca lista sin confirmar alimentación | E36: Código + prueba en celda | F36: Programador robot | G36: KRC/R1/Program/Centerline/PRELOAD.src, KRC/R1/System/$config.dat, KRC/R1/Program/StyleApps/Options/style1app1opt1.src, KRC/R1/Program/StyleApps/Options/style1app1opt2.src, KRC/R1/Program/StyleApps/Options/style1app1opt3.src | H36: • En PRELOAD toda condición que la secuencia espera (QFP regresado/avanzado en los pasos 0 y 10, QFP regresado al final del paso 20, $IN[481] dipw1_FeedComplt) tiene timeout; al vencer: NUT_PRELOAD_FAULT = TRUE, queda registrado el paso y la señal, y la secuencia no pone NUT_READY ni NEXT_NUT_READY. • PRELOAD no contiene WAIT FOR ni WAIT SEC (corre en el submit). • Existe al menos una asignación NUT_PRELOAD_FAULT = TRUE en código activo, y la falla solo se borra en un punto definido (reset del operador o rutina de reset), dicho en el comentario. • Fuera de dry cycle, NUT_READY / NEXT_NUT_READY = TRUE solo con $IN[481] visto ON durante la alimentación, $IN[480] en nivel OK (polaridad confirmada) y QFP regresado confirmado al final del paso 20. • En style1app1opt1..3 la espera previa al LIN de aproximación termina con la bandera de tuerca lista o con NUT_PRELOAD_FAULT; con falla hay mensaje, $OUT[4] do004ProcessFault ON y el robot no ejecuta el LIN de aproximación. • Prueba en celda: (a) tolva vacía o alimentador apagado: no hay tuerca lista, aparece el mensaje y el robot no entra al pedestal; (b) aire del QFP cerrado: timeout del paso con mensaje. Anotar fecha, timeout y texto del mensaje. • Comentarios del código cambiado según docs/CONVENTIONS.md (inglés, señal con dirección y nombre); ningún encabezado de inline form ni línea dentro de un fold de form cambia sin estar declarado (F32, F21, F31). | I36: F01, F11 | J36: Abierto | O36: Avance parcial (F52) | P36: 2026-10-07 | Q36: El paso 20 ya termina con el QFP regresado confirmado ($IN[482] ON, $IN[470] OFF) en vez de 800 ms. Timeouts, falla y feed complete siguen pendientes.
A37: F14 | B37: Calvin #11 | C37: Medio | D37: NUT_READY no se consume al soldar; la siguiente tuerca depende solo de TRIGGERs | E37: Código + prueba en celda | F37: Programador robot | G37: KRC/R1/Program/Centerline/centerline_weld.src, KRC/R1/Program/Centerline/PRELOAD.src, KRC/R1/Program/Centerline/Request_next_nut.src, KRC/R1/Program/StyleApps/Options/style1app1opt1.src, KRC/R1/Program/StyleApps/Options/style1app1opt2.src, KRC/R1/Program/StyleApps/Options/style1app1opt3.src, KRC/R1/Program/StylePicks/Options/style1pick1opt1.src, KRC/R1/Program/StylePicks/Options/style1pick1opt2.src, KRC/R1/Program/StylePicks/Options/style1pick1opt1AutoRR.src, KRC/R1/System/$config.dat | H37: • En CENTERLINE_WELD después de $IN[483] dipw1_WeldComplete, o inmediatamente después de CENTERLINE_WELD() en style1app1opt1..3, existe NUT_READY = FALSE (y la bandera que usen las tuercas 2 y 3) antes de salir del pedestal. • La petición de la tuerca 1 (picks) y de las tuercas 2 y 3 (final de style1app1opt1 y opt2) existe como instrucción en el flujo, fuera de TRIGGER, precedida de un paro de advance run; en las apps va después del movimiento que saca pieza y EOAT del alcance del QFP y de los pines. • En PRELOAD una petición que llega con preload activo o con tuerca cargada sin consumir no arranca otra alimentación. • Antes de alimentar se confirma pin vacío: por sensor si existe (nombre y dirección), o por estado si se confirma en sitio que no hay sensor; el comentario del paso dice cuál. • El pick red rabbit no pide preload, o la lista anota por qué sí. • Prueba en celda: (a) cancelar el ciclo con tuerca precargada y reiniciar desde home: no hay doble tuerca; (b) cancelar después de soldar la tuerca 1 y reiniciar con selección de paso en style1app1opt2: el robot no entra a soldar sin preload nuevo. Anotar fecha y resultado. • Comentarios del código cambiado según docs/CONVENTIONS.md (inglés, señal con dirección y nombre); ningún encabezado de inline form ni línea dentro de un fold de form cambia sin estar declarado (F32, F21, F31). | I37: F11, F25, F32, F38 | J37: Abierto | O37: Alta (Ethos) | P37: 2026-10-04 | Q37: Revisión Ethos del respaldo 658424 (v431_03_10_r1.zip del 2026-10-02).
A38: F15 | B38: Calvin #1 | C38: Medio | D38: Unos 35 WAIT FOR sobre entradas de proceso sin timeout ni mensaje | E38: Código + prueba en celda | F38: Programador robot | G38: KRC/R1/Program/Centerline/centerline_weld.src, KRC/R1/Program/StyleApps/Options/style1app1opt1.src, KRC/R1/Program/StyleApps/Options/style1app1opt2.src, KRC/R1/Program/StyleApps/Options/style1app1opt3.src, KRC/R1/Program/StylePicks/Options/style1pick1opt1.src, KRC/R1/Program/StylePicks/Options/style1pick1opt2.src, KRC/R1/Program/StylePicks/Options/style1pick1opt1AutoRR.src, KRC/R1/Program/StyleDrops/Options/style1drop1opt1.src, KRC/R1/Program/StyleDrops/Options/style1drop1opt2AutoRR.src, KRC/R1/Program/Utilities/RejectGE4.src, KRC/R1/Program/StyleApps/Options/style1app2opt2.src, KRC/R1/cell.src, KRC/R1/Program/Centerline/CENTERLINE_HOME.src, KRC/R1/Program/Utilities/gunelectrodechange.src | H38: • En los módulos listados no queda espera sin timeout sobre $IN[466], $IN[467], $IN[470], $IN[479] dipw1_IntensfPresOk, $IN[482], $IN[483], $IN[484], CL_GunStrokePositionLPT, NUT_READY, NEXT_NUT_READY, $IN[80] di080ToolRepositioned1 ni $IN[253]/$IN[254]. • Al vencer un timeout: $OUT[4] do004ProcessFault ON, mensaje que nombra la señal con dirección, y el programa no continúa sin la condición (reintento o abort explícito). • En CENTERLINE_WELD y CENTERLINE_HOME el abort de una espera vencida deja el pedestal abierto: primero $OUT[483] dopw1_WeldInit OFF, luego gun abierto y clamp abierto. • En cell.src la espera de $IN[8] di008ReturnFromRepair tiene al menos mensaje de espera que nombra la señal. • La lista trae una tabla módulo / señal / timeout (s) / reacción que coincide con el código del respaldo. • Prueba en T1: provocar una espera vencida por grupo: pedestal (clamp sin aire), intensificado ($IN[479]), cámara ($IN[80] sin respuesta), Bosch (ready ausente) y gripper (pieza presente); anotar mensaje, $OUT[4] y fecha. • Comentarios del código cambiado según docs/CONVENTIONS.md (inglés, señal con dirección y nombre); ningún encabezado de inline form ni línea dentro de un fold de form cambia sin estar declarado (F32, F21, F31). | I38: F01, F07, F10 | J38: Abierto | O38: Alta (Ethos) | P38: 2026-10-04 | Q38: Revisión Ethos del respaldo 658424 (v431_03_10_r1.zip del 2026-10-02).
A39: F16 | B39: Ethos | C39: Medio | D39: Posición del pin superior nunca verificada | E39: Código + prueba en celda | F39: Programador robot / Puesta en marcha | G39: KRC/R1/Program/Centerline/centerline_weld.src, KRC/R1/System/$config.dat, KRC/R1/System/sps.sub | H39: • En CENTERLINE_WELD, antes de dopw1_WeldInit = TRUE, hay espera supervisada (timeout + mensaje + $OUT[4] do004ProcessFault) de CL_WeldPinPosition dentro de CL_PIN_WELD_MIN..CL_PIN_WELD_MAX. • Después del comando de retraer ($OUT[499] do499UpperPinRetract ON) y antes del END hay espera supervisada de CL_WeldPinPosition dentro de una ventana de retraído declarada como constantes en $config.dat. • Las ventanas coinciden con los valores medidos anotados en la lista (la tabla del encabezado da retraído 27252, extendido 6602, soldadura 11674) y no se traslapan; la tabla del encabezado coincide con las constantes. • Las ventanas del gun usan CL_GUN_WELD_MIN/MAX y CL_GUN_OPEN_MIN (hecho en oficina, G16). • Prueba en celda en T1: provocar que el pin superior no llegue a la ventana de soldadura: no hay weld start y aparece el mensaje; anotar fecha y resultado. • Comentarios del código cambiado según docs/CONVENTIONS.md (inglés, señal con dirección y nombre); ningún encabezado de inline form ni línea dentro de un fold de form cambia sin estar declarado (F32, F21, F31). | I39: F27 | J39: Abierto | O39: Alta (Ethos) | P39: 2026-10-04 | Q39: Revisión Ethos del respaldo 658424 (v431_03_10_r1.zip del 2026-10-02).
A40: F17 | B40: Ethos | C40: Medio | D40: Declaraciones traslapadas; nombres dobles en los bits del pedestal | E40: Código | F40: Programador robot | G40: KRC/R1/System/$config.dat, KRC/R1/TP/AutomationCore/automationcoreroutines.dat, KRC/R1/TP/NutWeld/nutweldroutines.dat | H40: • $IN[466], $IN[467], $IN[470], $OUT[498], $OUT[499] y $OUT[501..505] tienen nombre AutomationCore y el código del pedestal no usa direcciones literales (hecho en oficina, G12). • Las declaraciones de pistola 2/3 que se traslapan con CL_GunPressureCmd, CL_LPT_BYTE0..3 y CL_PIN_BYTE0/1 y los nombres Spare de $IN[466/467/470] llevan comentario de retirados, y ningún programa del integrador los lee ni escribe. • $OUT[477]/$OUT[478]: el comentario de la declaración dice cuál nombre es el correcto (confirmado con F29). • $OUT[500] recibe nombre después de confirmar en celda qué mueve, o deja de usarse. • Ninguna dirección cambió; cada edición en archivos del proveedor (automationcoreroutines.dat, nutweldroutines.dat) aparece en la lista de C28. • Comentarios del código cambiado según docs/CONVENTIONS.md (inglés, señal con dirección y nombre); ningún encabezado de inline form ni línea dentro de un fold de form cambia sin estar declarado (F32, F21, F31). | I40: F29 | J40: Abierto | O40: Alta (Ethos) | P40: 2026-10-04 | Q40: Revisión Ethos del respaldo 658424 (v431_03_10_r1.zip del 2026-10-02).
...

Sheet Resumen
A1: Resumen de puntos abiertos
A2: Generado 2026-10-11 07:29 (hora del centro de México)
A3: Estado | B3: Puntos
A4: Abierto | B4: =COUNTIF('Puntos abiertos'!$J$2:$J$103,A4)
A5: Requiere decisión | B5: =COUNTIF('Puntos abiertos'!$J$2:$J$103,A5)
A6: En proceso | B6: =COUNTIF('Puntos abiertos'!$J$2:$J$103,A6)
A7: Corregido - por auditar | B7: =COUNTIF('Puntos abiertos'!$J$2:$J$103,A7)
A8: Cerrado - auditado | B8: =COUNTIF('Puntos abiertos'!$J$2:$J$103,A8)
A9: Reabierto | B9: =COUNTIF('Puntos abiertos'!$J$2:$J$103,A9)
A10: Aceptado sin cambio | B10: =COUNTIF('Puntos abiertos'!$J$2:$J$103,A10)
A11: Cerrado - depuración | B11: =COUNTIF('Puntos abiertos'!$J$2:$J$103,A11)
A12: No aplica | B12: =COUNTIF('Puntos abiertos'!$J$2:$J$103,A12)
A13: Sin acción - documentado | B13: =COUNTIF('Puntos abiertos'!$J$2:$J$103,A13)
A14: Se cierra con otro punto | B14: =COUNTIF('Puntos abiertos'!$J$2:$J$103,A14)
A15: Total | B15: =SUM(B4:B14)
A17: Severidad | B17: Total | C17: Pendientes
A18: Crítico | B18: =COUNTIF('Puntos abiertos'!$C$2:$C$103,A18) | C18: =COUNTIFS('Puntos abiertos'!$C$2:$C$103,A18,'Puntos abiertos'!$J$2:$J$103,"Abierto")+COUNTIFS('Puntos abiertos'!$C$2:$C$103,A18,'Puntos abiertos'!$J$2:$J$103,"Requiere decisión")+COUNTIFS('Puntos abiertos'!$C$2:$C$103,A18,'Puntos abiertos'!$J$2:$J$103,"En proceso")+COUNTIFS('Puntos abiertos'!$C$2:$C$103,A18,'Puntos abiertos'!$J$2:$J$103,"Corregido - por auditar")+COUNTIFS('Puntos abiertos'!$C$2:$C$103,A18,'Puntos abiertos'!$J$2:$J$103,"Reabierto")
A19: Alto | B19: =COUNTIF('Puntos abiertos'!$C$2:$C$103,A19) | C19: =COUNTIFS('Puntos abiertos'!$C$2:$C$103,A19,'Puntos abiertos'!$J$2:$J$103,"Abierto")+COUNTIFS('Puntos abiertos'!$C$2:$C$103,A19,'Puntos abiertos'!$J$2:$J$103,"Requiere decisión")+COUNTIFS('Puntos abiertos'!$C$2:$C$103,A19,'Puntos abiertos'!$J$2:$J$103,"En proceso")+COUNTIFS('Puntos abiertos'!$C$2:$C$103,A19,'Puntos abiertos'!$J$2:$J$103,"Corregido - por auditar")+COUNTIFS('Puntos abiertos'!$C$2:$C$103,A19,'Puntos abiertos'!$J$2:$J$103,"Reabierto")
A20: Medio | B20: =COUNTIF('Puntos abiertos'!$C$2:$C$103,A20) | C20: =COUNTIFS('Puntos abiertos'!$C$2:$C$103,A20,'Puntos abiertos'!$J$2:$J$103,"Abierto")+COUNTIFS('Puntos abiertos'!$C$2:$C$103,A20,'Puntos abiertos'!$J$2:$J$103,"Requiere decisión")+COUNTIFS('Puntos abiertos'!$C$2:$C$103,A20,'Puntos abiertos'!$J$2:$J$103,"En proceso")+COUNTIFS('Puntos abiertos'!$C$2:$C$103,A20,'Puntos abiertos'!$J$2:$J$103,"Corregido - por auditar")+COUNTIFS('Puntos abiertos'!$C$2:$C$103,A20,'Puntos abiertos'!$J$2:$J$103,"Reabierto")
A21: Bajo | B21: =COUNTIF('Puntos abiertos'!$C$2:$C$103,A21) | C21: =COUNTIFS('Puntos abiertos'!$C$2:$C$103,A21,'Puntos abiertos'!$J$2:$J$103,"Abierto")+COUNTIFS('Puntos abiertos'!$C$2:$C$103,A21,'Puntos abiertos'!$J$2:$J$103,"Requiere decisión")+COUNTIFS('Puntos abiertos'!$C$2:$C$103,A21,'Puntos abiertos'!$J$2:$J$103,"En proceso")+COUNTIFS('Puntos abiertos'!$C$2:$C$103,A21,'Puntos abiertos'!$J$2:$J$103,"Corregido - por auditar")+COUNTIFS('Puntos abiertos'!$C$2:$C$103,A21,'Puntos abiertos'!$J$2:$J$103,"Reabierto")
A23: Origen | B23: Total | C23: Pendientes
A24: Gestamp | B24: =COUNTIF('Puntos abiertos'!$B$2:$B$103,"Gestamp*") | C24: =COUNTIFS('Puntos abiertos'!$B$2:$B$103,"Gestamp*",'Puntos abiertos'!$J$2:$J$103,"Abierto")+COUNTIFS('Puntos abiertos'!$B$2:$B$103,"Gestamp*",'Puntos abiertos'!$J$2:$J$103,"Requiere decisión")+COUNTIFS('Puntos abiertos'!$B$2:$B$103,"Gestamp*",'Puntos abiertos'!$J$2:$J$103,"En proceso")+COUNTIFS('Puntos abiertos'!$B$2:$B$103,"Gestamp*",'Puntos abiertos'!$J$2:$J$103,"Corregido - por auditar")+COUNTIFS('Puntos abiertos'!$B$2:$B$103,"Gestamp*",'Puntos abiertos'!$J$2:$J$103,"Reabierto")
